<?xml version="1.0"?>
<robot name="modular-robot">
	<link name="part0">
		<visual>
			<origin rpy="0.000000 -0.000000 0.000000" xyz="0.000000 0.000000 0.100000"/>
			<geometry>
				<mesh filename="stl_files/B_simple.STL"/>
			</geometry>
			<material name="color-0">
				<color rgba="1.000000 1.000000 1.000000 1.000000"/>
			</material>
		</visual>
		<collision>
			<origin rpy="0.000000 -0.000000 0.000000" xyz="0.000000 0.000000 0.100000"/>
			<geometry>
				<mesh filename="stl_files/B_simple.STL"/>
			</geometry>
		</collision>
	</link>
	<link name="part2">
		<inertial>
			<origin rpy="0.000000 0.000000 0.000000" xyz="0.000630 0.000190 -0.009660"/>
			<mass value="0.588000"/>
			<inertia ixx="0.000840" ixy="0.000000" ixz="-0.000011" iyy="0.000833" iyz="-0.000001" izz="0.000732"/>
		</inertial>
	</link>
	<link name="part1">
		<inertial>
			<origin rpy="0.000000 0.000000 0.000000" xyz="0.000180 0.000130 0.054300"/>
			<mass value="2.795000"/>
			<inertia ixx="0.014000" ixy="-0.000002" ixz="-0.000003" iyy="0.014000" iyz="0.000005" izz="0.000732"/>
		</inertial>
		<visual>
			<origin rpy="0.000000 -0.000000 0.000000" xyz="0.000000 0.000000 0.135300"/>
			<geometry>
				<mesh filename="stl_files/MXL+90.STL"/>
			</geometry>
			<material name="color-1">
				<color rgba="0.100000 0.100000 0.500000 1.000000"/>
			</material>
		</visual>
		<collision>
			<origin rpy="0.000000 -0.000000 0.000000" xyz="0.000000 0.000000 0.135300"/>
			<geometry>
				<mesh filename="stl_files/MXL+90.STL"/>
			</geometry>
		</collision>
	</link>
	<link name="part3">
		<inertial>
			<origin rpy="0.000000 0.000000 0.000000" xyz="0.000200 -0.036560 0.054520"/>
			<mass value="0.581910"/>
			<inertia ixx="0.004886" ixy="-0.000007" ixz="0.000007" iyy="0.003453" iyz="-0.001714" izz="0.000000"/>
		</inertial>
		<visual>
			<origin rpy="2.356194 -1.570796 2.356194" xyz="0.000000 -0.065500 0.100900"/>
			<geometry>
				<mesh filename="stl_files/L_Rasmus_01_90_LL.STL"/>
			</geometry>
			<material name="color-3">
				<color rgba="1.000000 1.000000 1.000000 1.000000"/>
			</material>
		</visual>
		<collision>
			<origin rpy="2.356194 -1.570796 2.356194" xyz="0.000000 -0.065500 0.100900"/>
			<geometry>
				<mesh filename="stl_files/L_Rasmus_01_90_LL.STL"/>
			</geometry>
		</collision>
	</link>
	<link name="part5">
		<inertial>
			<origin rpy="0.000000 0.000000 0.000000" xyz="0.000630 0.000190 -0.009660"/>
			<mass value="0.588000"/>
			<inertia ixx="0.000840" ixy="0.000000" ixz="-0.000011" iyy="0.000833" iyz="-0.000001" izz="0.000732"/>
		</inertial>
	</link>
	<link name="part4">
		<inertial>
			<origin rpy="0.000000 0.000000 0.000000" xyz="0.000180 0.000130 0.054300"/>
			<mass value="2.795000"/>
			<inertia ixx="0.014000" ixy="-0.000002" ixz="-0.000003" iyy="0.014000" iyz="0.000005" izz="0.000732"/>
		</inertial>
		<visual>
			<origin rpy="0.000000 -0.000000 0.000000" xyz="0.000000 0.000000 0.135300"/>
			<geometry>
				<mesh filename="stl_files/MXL.STL"/>
			</geometry>
			<material name="color-4">
				<color rgba="0.100000 0.100000 0.500000 1.000000"/>
			</material>
		</visual>
		<collision>
			<origin rpy="0.000000 -0.000000 0.000000" xyz="0.000000 0.000000 0.135300"/>
			<geometry>
				<mesh filename="stl_files/MXL.STL"/>
			</geometry>
		</collision>
	</link>
	<link name="part6">
		<inertial>
			<origin rpy="0.000000 0.000000 0.000000" xyz="0.196128 0.000005 0.044778"/>
			<mass value="1.591660"/>
			<inertia ixx="0.005537" ixy="0.000002" ixz="0.014137" iyy="0.093690" iyz="0.000001" izz="0.000000"/>
		</inertial>
		<visual>
			<origin rpy="-3.141593 -0.000000 0.000000" xyz="0.400000 0.000000 0.000000"/>
			<geometry>
				<mesh filename="stl_files/L_360_400_LS.STL"/>
			</geometry>
			<material name="color-6">
				<color rgba="1.000000 1.000000 1.000000 1.000000"/>
			</material>
		</visual>
		<collision>
			<origin rpy="-3.141593 -0.000000 0.000000" xyz="0.400000 0.000000 0.000000"/>
			<geometry>
				<mesh filename="stl_files/L_360_400_LS.STL"/>
			</geometry>
		</collision>
	</link>
	<link name="part8">
		<inertial>
			<origin rpy="0.000000 0.000000 0.000000" xyz="-0.000030 0.000010 -0.015900"/>
			<mass value="0.473600"/>
			<inertia ixx="0.000536" ixy="-0.000000" ixz="-0.000000" iyy="0.000536" iyz="0.000000" izz="0.000564"/>
		</inertial>
	</link>
	<link name="part7">
		<inertial>
			<origin rpy="0.000000 0.000000 0.000000" xyz="0.000025 0.001030 0.050400"/>
			<mass value="2.139300"/>
			<inertia ixx="0.009000" ixy="0.000002" ixz="-0.000002" iyy="0.008000" iyz="0.000024" izz="0.000564"/>
		</inertial>
		<visual>
			<origin rpy="0.000000 -0.000000 0.000000" xyz="0.000000 0.000000 0.127600"/>
			<geometry>
				<mesh filename="stl_files/ML.STL"/>
			</geometry>
			<material name="color-7">
				<color rgba="0.100000 0.100000 0.500000 1.000000"/>
			</material>
		</visual>
		<collision>
			<origin rpy="0.000000 -0.000000 0.000000" xyz="0.000000 0.000000 0.127600"/>
			<geometry>
				<mesh filename="stl_files/ML.STL"/>
			</geometry>
		</collision>
	</link>
	<link name="part9">
		<inertial>
			<origin rpy="0.000000 0.000000 0.000000" xyz="0.060011 0.005268 0.039688"/>
			<mass value="0.578517"/>
			<inertia ixx="0.002063" ixy="0.000340" ixz="0.001596" iyy="0.005676" iyz="0.000134" izz="0.000000"/>
		</inertial>
		<visual>
			<origin rpy="-1.570796 -0.000000 0.000000" xyz="0.114000 0.047000 0.047000"/>
			<geometry>
				<mesh filename="stl_files/L_90S_compact_LL_actual.STL"/>
			</geometry>
			<material name="color-9">
				<color rgba="1.000000 1.000000 1.000000 1.000000"/>
			</material>
		</visual>
		<collision>
			<origin rpy="-1.570796 -0.000000 0.000000" xyz="0.114000 0.047000 0.047000"/>
			<geometry>
				<mesh filename="stl_files/L_90S_compact_LL_actual.STL"/>
			</geometry>
		</collision>
	</link>
	<link name="part11">
		<inertial>
			<origin rpy="0.000000 0.000000 0.000000" xyz="-0.000030 0.000010 -0.015900"/>
			<mass value="0.473600"/>
			<inertia ixx="0.000536" ixy="-0.000000" ixz="-0.000000" iyy="0.000536" iyz="0.000000" izz="0.000564"/>
		</inertial>
	</link>
	<link name="part10">
		<inertial>
			<origin rpy="0.000000 0.000000 0.000000" xyz="0.000025 0.001030 0.050400"/>
			<mass value="2.139300"/>
			<inertia ixx="0.009000" ixy="0.000002" ixz="-0.000002" iyy="0.008000" iyz="0.000024" izz="0.000564"/>
		</inertial>
		<visual>
			<origin rpy="0.000000 -0.000000 0.000000" xyz="0.000000 0.000000 0.127600"/>
			<geometry>
				<mesh filename="stl_files/ML.STL"/>
			</geometry>
			<material name="color-10">
				<color rgba="0.100000 0.100000 0.500000 1.000000"/>
			</material>
		</visual>
		<collision>
			<origin rpy="0.000000 -0.000000 0.000000" xyz="0.000000 0.000000 0.127600"/>
			<geometry>
				<mesh filename="stl_files/ML.STL"/>
			</geometry>
		</collision>
	</link>
	<link name="part12">
		<inertial>
			<origin rpy="0.000000 0.000000 0.000000" xyz="0.000006 0.091445 0.125960"/>
			<mass value="1.677416"/>
			<inertia ixx="0.107697" ixy="0.000001" ixz="0.000003" iyy="0.091364" iyz="0.034625" izz="0.000000"/>
		</inertial>
		<visual>
			<origin rpy="1.570796 -0.000000 0.000000" xyz="0.000000 0.065000 0.250000"/>
			<geometry>
				<mesh filename="stl_files/L_90L_250_LS_actual.STL"/>
			</geometry>
			<material name="color-12">
				<color rgba="1.000000 1.000000 1.000000 1.000000"/>
			</material>
		</visual>
		<collision>
			<origin rpy="1.570796 -0.000000 0.000000" xyz="0.000000 0.065000 0.250000"/>
			<geometry>
				<mesh filename="stl_files/L_90L_250_LS_actual.STL"/>
			</geometry>
		</collision>
	</link>
	<link name="part14">
		<inertial>
			<origin rpy="0.000000 0.000000 0.000000" xyz="-0.000044 -0.000008 -0.001115"/>
			<mass value="0.289400"/>
			<inertia ixx="0.000178" ixy="-0.000000" ixz="-0.000000" iyy="0.000178" iyz="0.000000" izz="0.000192"/>
		</inertial>
	</link>
	<link name="part13">
		<inertial>
			<origin rpy="0.000000 0.000000 0.000000" xyz="0.000610 0.000080 0.047140"/>
			<mass value="1.253380"/>
			<inertia ixx="0.004000" ixy="0.000000" ixz="0.000016" iyy="0.005000" iyz="-0.000000" izz="0.000192"/>
		</inertial>
		<visual>
			<origin rpy="0.000000 -0.000000 0.000000" xyz="0.000000 0.000000 0.119550"/>
			<geometry>
				<mesh filename="stl_files/MS.STL"/>
			</geometry>
			<material name="color-13">
				<color rgba="0.100000 0.100000 0.500000 1.000000"/>
			</material>
		</visual>
		<collision>
			<origin rpy="0.000000 -0.000000 0.000000" xyz="0.000000 0.000000 0.119550"/>
			<geometry>
				<mesh filename="stl_files/MS.STL"/>
			</geometry>
		</collision>
	</link>
	<link name="part15">
		<inertial>
			<origin rpy="0.000000 0.000000 0.000000" xyz="-0.043600 0.035200 -0.023740"/>
			<mass value="0.337890"/>
			<inertia ixx="0.001553" ixy="-0.000777" ixz="0.000685" iyy="0.001824" iyz="-0.000526" izz="0.000000"/>
		</inertial>
		<visual>
			<origin rpy="1.570796 3.141593 1.570796" xyz="-0.060000 0.063000 -0.058000"/>
			<geometry>
				<mesh filename="stl_files/L_Rasmus_02_90_SS.STL"/>
			</geometry>
			<material name="color-15">
				<color rgba="1.000000 1.000000 1.000000 1.000000"/>
			</material>
		</visual>
		<collision>
			<origin rpy="1.570796 3.141593 1.570796" xyz="-0.060000 0.063000 -0.058000"/>
			<geometry>
				<mesh filename="stl_files/L_Rasmus_02_90_SS.STL"/>
			</geometry>
		</collision>
	</link>
	<link name="part17">
		<inertial>
			<origin rpy="0.000000 0.000000 0.000000" xyz="-0.000044 -0.000008 -0.001115"/>
			<mass value="0.289400"/>
			<inertia ixx="0.000178" ixy="-0.000000" ixz="-0.000000" iyy="0.000178" iyz="0.000000" izz="0.000192"/>
		</inertial>
	</link>
	<link name="part16">
		<inertial>
			<origin rpy="0.000000 0.000000 0.000000" xyz="0.000610 0.000080 0.047140"/>
			<mass value="1.253380"/>
			<inertia ixx="0.004000" ixy="0.000000" ixz="0.000016" iyy="0.005000" iyz="-0.000000" izz="0.000192"/>
		</inertial>
		<visual>
			<origin rpy="0.000000 -0.000000 0.000000" xyz="0.000000 0.000000 0.119550"/>
			<geometry>
				<mesh filename="stl_files/MS.STL"/>
			</geometry>
			<material name="color-16">
				<color rgba="0.100000 0.100000 0.500000 1.000000"/>
			</material>
		</visual>
		<collision>
			<origin rpy="0.000000 -0.000000 0.000000" xyz="0.000000 0.000000 0.119550"/>
			<geometry>
				<mesh filename="stl_files/MS.STL"/>
			</geometry>
		</collision>
	</link>
	<link name="tool_dummy">
		<inertial>
			<origin rpy="0.000000 0.000000 0.000000" xyz="0.000000 0.000000 0.000000"/>
			<mass value="0.000000"/>
			<inertia ixx="0.000000" ixy="0.000000" ixz="0.000000" iyy="0.000000" iyz="0.000000" izz="0.000000"/>
		</inertial>
	</link>
	<link name="part18">
		<inertial>
			<origin rpy="0.000000 0.000000 0.000000" xyz="0.000000 0.000000 0.000000"/>
			<mass value="1.000000"/>
			<inertia ixx="0.000000" ixy="0.000000" ixz="0.000000" iyy="0.000000" iyz="0.000000" izz="0.000000"/>
		</inertial>
		<visual>
			<origin rpy="3.141593 -3.141593 3.089233" xyz="0.000000 0.000000 0.121000"/>
			<geometry>
				<mesh filename="stl_files/E_Schimaneck.STL"/>
			</geometry>
			<material name="color-18">
				<color rgba="1.000000 1.000000 1.000000 1.000000"/>
			</material>
		</visual>
		<collision>
			<origin rpy="3.141593 -3.141593 3.089233" xyz="0.000000 0.000000 0.121000"/>
			<geometry>
				<mesh filename="stl_files/E_Schimaneck.STL"/>
			</geometry>
		</collision>
	</link>
	<joint name="part0_part1" type="fixed">
		<origin xyz="0.000000 0.000000 0.100000" rpy="0.000000 -0.000000 0.000000"/>
		<parent link="part0"/>
		<child link="part1"/>
		<axis xyz="0.000000 0.000000 0.000000"/>
	</joint>
	<joint name="part2_part3" type="fixed">
		<origin xyz="0.000000 0.000000 0.067650" rpy="0.000000 -0.000000 0.000000"/>
		<parent link="part2"/>
		<child link="part3"/>
		<axis xyz="0.000000 0.000000 0.000000"/>
	</joint>
	<joint name="joint0" type="revolute">
		<origin xyz="0.000000 0.000000 0.067650" rpy="0.000000 -0.000000 0.000000"/>
		<parent link="part1"/>
		<child link="part2"/>
		<axis xyz="0.000000 0.000000 1.000000"/>
		<limit effort="0.000000" velocity="0.000000" lower="-3.141593" upper="3.141593"/>
	</joint>
	<joint name="part3_part4" type="fixed">
		<origin xyz="0.000000 -0.065500 0.100900" rpy="2.356194 -1.570796 2.356194"/>
		<parent link="part3"/>
		<child link="part4"/>
		<axis xyz="0.000000 0.000000 0.000000"/>
	</joint>
	<joint name="part5_part6" type="fixed">
		<origin xyz="0.000000 0.000000 0.067650" rpy="0.000000 -0.000000 0.000000"/>
		<parent link="part5"/>
		<child link="part6"/>
		<axis xyz="0.000000 0.000000 0.000000"/>
	</joint>
	<joint name="joint1" type="revolute">
		<origin xyz="0.000000 0.000000 0.067650" rpy="0.000000 -0.000000 0.000000"/>
		<parent link="part4"/>
		<child link="part5"/>
		<axis xyz="0.000000 0.000000 1.000000"/>
		<limit effort="0.000000" velocity="0.000000" lower="-3.141593" upper="3.141593"/>
	</joint>
	<joint name="part6_part7" type="fixed">
		<origin xyz="0.400000 0.000000 0.000000" rpy="-3.141593 -0.000000 0.000000"/>
		<parent link="part6"/>
		<child link="part7"/>
		<axis xyz="0.000000 0.000000 0.000000"/>
	</joint>
	<joint name="part8_part9" type="fixed">
		<origin xyz="0.000000 0.000000 0.063800" rpy="0.000000 -0.000000 0.000000"/>
		<parent link="part8"/>
		<child link="part9"/>
		<axis xyz="0.000000 0.000000 0.000000"/>
	</joint>
	<joint name="joint2" type="revolute">
		<origin xyz="0.000000 0.000000 0.063800" rpy="0.000000 -0.000000 0.000000"/>
		<parent link="part7"/>
		<child link="part8"/>
		<axis xyz="0.000000 0.000000 1.000000"/>
		<limit effort="0.000000" velocity="0.000000" lower="-3.141593" upper="3.141593"/>
	</joint>
	<joint name="part9_part10" type="fixed">
		<origin xyz="0.114000 0.047000 0.047000" rpy="-1.570796 -0.000000 0.000000"/>
		<parent link="part9"/>
		<child link="part10"/>
		<axis xyz="0.000000 0.000000 0.000000"/>
	</joint>
	<joint name="part11_part12" type="fixed">
		<origin xyz="0.000000 0.000000 0.063800" rpy="0.000000 -0.000000 0.000000"/>
		<parent link="part11"/>
		<child link="part12"/>
		<axis xyz="0.000000 0.000000 0.000000"/>
	</joint>
	<joint name="joint3" type="revolute">
		<origin xyz="0.000000 0.000000 0.063800" rpy="0.000000 -0.000000 0.000000"/>
		<parent link="part10"/>
		<child link="part11"/>
		<axis xyz="0.000000 0.000000 1.000000"/>
		<limit effort="0.000000" velocity="0.000000" lower="-3.141593" upper="3.141593"/>
	</joint>
	<joint name="part12_part13" type="fixed">
		<origin xyz="0.000000 0.065000 0.250000" rpy="1.570796 -0.000000 0.000000"/>
		<parent link="part12"/>
		<child link="part13"/>
		<axis xyz="0.000000 0.000000 0.000000"/>
	</joint>
	<joint name="part14_part15" type="fixed">
		<origin xyz="0.000000 0.000000 0.059775" rpy="0.000000 -0.000000 0.000000"/>
		<parent link="part14"/>
		<child link="part15"/>
		<axis xyz="0.000000 0.000000 0.000000"/>
	</joint>
	<joint name="joint4" type="revolute">
		<origin xyz="0.000000 0.000000 0.059775" rpy="0.000000 -0.000000 0.000000"/>
		<parent link="part13"/>
		<child link="part14"/>
		<axis xyz="0.000000 0.000000 1.000000"/>
		<limit effort="0.000000" velocity="0.000000" lower="-3.141593" upper="3.141593"/>
	</joint>
	<joint name="part15_part16" type="fixed">
		<origin xyz="-0.060000 0.063000 -0.058000" rpy="1.570796 3.141593 1.570796"/>
		<parent link="part15"/>
		<child link="part16"/>
		<axis xyz="0.000000 0.000000 0.000000"/>
	</joint>
	<joint name="part17_part18" type="fixed">
		<origin xyz="0.000000 0.000000 0.059775" rpy="0.000000 -0.000000 0.000000"/>
		<parent link="part17"/>
		<child link="part18"/>
		<axis xyz="0.000000 0.000000 0.000000"/>
	</joint>
	<joint name="joint5" type="revolute">
		<origin xyz="0.000000 0.000000 0.059775" rpy="0.000000 -0.000000 0.000000"/>
		<parent link="part16"/>
		<child link="part17"/>
		<axis xyz="0.000000 0.000000 1.000000"/>
		<limit effort="0.000000" velocity="0.000000" lower="-3.141593" upper="3.141593"/>
	</joint>
	<joint name="part18_tool_dummy" type="fixed">
		<origin xyz="0.000000 0.000000 0.121000" rpy="3.141593 -3.141593 3.089233"/>
		<parent link="part18"/>
		<child link="tool_dummy"/>
		<axis xyz="0.000000 0.000000 0.000000"/>
	</joint>
</robot>
