<?xml version="1.0"?>
<robot name="modular-robot">
	<link name="part0">
		<visual>
			<origin rpy="0.000000 0.000000 0.000000" xyz="0.000000 0.000000 0.000000"/>
			<geometry>
				<mesh filename="ModuleLibrary/B-116-90deg/B-116-90deg.stl"/>
			</geometry>
			<material name="color-0">
				<color rgba="1.000000 1.000000 1.000000 1.000000"/>
			</material>
		</visual>
		<collision>
			<origin rpy="0.000000 0.000000 0.000000" xyz="0.000000 0.000000 0.000000"/>
			<geometry>
				<mesh filename="ModuleLibrary/B-116-90deg/B-116-90deg.stl"/>
			</geometry>
		</collision>
	</link>
	<link name="part2">
		<inertial>
			<origin rpy="0.000000 0.000000 0.000000" xyz="0.000013 0.000017 -0.030590"/>
			<mass value="0.529000"/>
			<inertia ixx="0.001085" ixy="0.000000" ixz="0.000000" iyy="0.001085" iyz="0.000000" izz="0.000438"/>
		</inertial>
		<visual>
			<origin rpy="0.000000 -0.000000 1.570796" xyz="0.000000 0.000000 0.070500"/>
			<geometry>
				<mesh filename="ModuleLibrary/D116/D116_distal.stl"/>
			</geometry>
			<material name="color-2">
				<color rgba="0.100000 0.100000 0.500000 1.000000"/>
			</material>
		</visual>
		<collision>
			<origin rpy="0.000000 -0.000000 1.570796" xyz="0.000000 0.000000 0.070500"/>
			<geometry>
				<mesh filename="ModuleLibrary/D116/D116_distal.stl"/>
			</geometry>
		</collision>
	</link>
	<link name="part1">
		<inertial>
			<origin rpy="0.000000 0.000000 0.000000" xyz="0.012065 0.000185 0.075993"/>
			<mass value="3.511000"/>
			<inertia ixx="0.024117" ixy="0.000033" ixz="-0.003083" iyy="0.024717" iyz="-0.000043" izz="0.005563"/>
		</inertial>
		<visual>
			<origin rpy="0.000000 0.000000 0.000000" xyz="0.000000 0.000000 0.000000"/>
			<geometry>
				<mesh filename="ModuleLibrary/D116/D116_proximal.stl"/>
			</geometry>
			<material name="color-1">
				<color rgba="0.100000 0.100000 0.500000 1.000000"/>
			</material>
		</visual>
		<collision>
			<origin rpy="0.000000 0.000000 0.000000" xyz="0.000000 0.000000 0.000000"/>
			<geometry>
				<mesh filename="ModuleLibrary/D116/D116_proximal.stl"/>
			</geometry>
		</collision>
	</link>
	<link name="part4">
		<inertial>
			<origin rpy="0.000000 0.000000 0.000000" xyz="0.000013 0.000017 -0.030590"/>
			<mass value="0.529000"/>
			<inertia ixx="0.001085" ixy="0.000000" ixz="0.000000" iyy="0.001085" iyz="0.000000" izz="0.000438"/>
		</inertial>
		<visual>
			<origin rpy="0.000000 -0.000000 1.570796" xyz="0.000000 0.000000 0.070500"/>
			<geometry>
				<mesh filename="ModuleLibrary/D116/D116_distal.stl"/>
			</geometry>
			<material name="color-4">
				<color rgba="0.100000 0.100000 0.500000 1.000000"/>
			</material>
		</visual>
		<collision>
			<origin rpy="0.000000 -0.000000 1.570796" xyz="0.000000 0.000000 0.070500"/>
			<geometry>
				<mesh filename="ModuleLibrary/D116/D116_distal.stl"/>
			</geometry>
		</collision>
	</link>
	<link name="part3">
		<inertial>
			<origin rpy="0.000000 0.000000 0.000000" xyz="0.012065 0.000185 0.075993"/>
			<mass value="3.511000"/>
			<inertia ixx="0.024117" ixy="0.000033" ixz="-0.003083" iyy="0.024717" iyz="-0.000043" izz="0.005563"/>
		</inertial>
		<visual>
			<origin rpy="0.000000 0.000000 0.000000" xyz="0.000000 0.000000 0.000000"/>
			<geometry>
				<mesh filename="ModuleLibrary/D116/D116_proximal.stl"/>
			</geometry>
			<material name="color-3">
				<color rgba="0.100000 0.100000 0.500000 1.000000"/>
			</material>
		</visual>
		<collision>
			<origin rpy="0.000000 0.000000 0.000000" xyz="0.000000 0.000000 0.000000"/>
			<geometry>
				<mesh filename="ModuleLibrary/D116/D116_proximal.stl"/>
			</geometry>
		</collision>
	</link>
	<link name="part5">
		<inertial>
			<origin rpy="0.000000 0.000000 0.000000" xyz="0.118904 0.000000 0.046614"/>
			<mass value="1.283000"/>
			<inertia ixx="0.003695" ixy="0.000000" ixz="-0.006953" iyy="0.030420" iyz="0.000000" izz="0.027966"/>
		</inertial>
		<visual>
			<origin rpy="0.000000 0.000000 0.000000" xyz="0.000000 0.000000 0.000000"/>
			<geometry>
				<mesh filename="ModuleLibrary/L283-L-80-80/L283-L-80-80.stl"/>
			</geometry>
			<material name="color-5">
				<color rgba="1.000000 1.000000 1.000000 1.000000"/>
			</material>
		</visual>
		<collision>
			<origin rpy="0.000000 0.000000 0.000000" xyz="0.000000 0.000000 0.000000"/>
			<geometry>
				<mesh filename="ModuleLibrary/L283-L-80-80/L283-L-80-80.stl"/>
			</geometry>
		</collision>
	</link>
	<link name="part7">
		<inertial>
			<origin rpy="0.000000 0.000000 0.000000" xyz="0.000000 0.000000 -0.022500"/>
			<mass value="0.282000"/>
			<inertia ixx="0.000287" ixy="0.000000" ixz="-0.000000" iyy="0.000287" iyz="-0.000000" izz="0.000122"/>
		</inertial>
	</link>
	<link name="part6">
		<inertial>
			<origin rpy="0.000000 0.000000 0.000000" xyz="0.000620 0.000180 0.058200"/>
			<mass value="1.780000"/>
			<inertia ixx="0.007580" ixy="0.000019" ixz="-0.000074" iyy="0.008140" iyz="-0.000016" izz="0.002150"/>
		</inertial>
		<visual>
			<origin rpy="0.000000 0.000000 0.000000" xyz="0.000000 0.000000 0.000000"/>
			<geometry>
				<mesh filename="ModuleLibrary/D86/D86.stl"/>
			</geometry>
			<material name="color-6">
				<color rgba="0.100000 0.100000 0.500000 1.000000"/>
			</material>
		</visual>
		<collision>
			<origin rpy="0.000000 0.000000 0.000000" xyz="0.000000 0.000000 0.000000"/>
			<geometry>
				<mesh filename="ModuleLibrary/D86/D86.stl"/>
			</geometry>
		</collision>
	</link>
	<link name="part9">
		<inertial>
			<origin rpy="0.000000 0.000000 0.000000" xyz="0.000000 0.000000 -0.022500"/>
			<mass value="0.282000"/>
			<inertia ixx="0.000287" ixy="0.000000" ixz="-0.000000" iyy="0.000287" iyz="-0.000000" izz="0.000122"/>
		</inertial>
	</link>
	<link name="part8">
		<inertial>
			<origin rpy="0.000000 0.000000 0.000000" xyz="0.000620 0.000180 0.058200"/>
			<mass value="1.780000"/>
			<inertia ixx="0.007580" ixy="0.000019" ixz="-0.000074" iyy="0.008140" iyz="-0.000016" izz="0.002150"/>
		</inertial>
		<visual>
			<origin rpy="0.000000 0.000000 0.000000" xyz="0.000000 0.000000 0.000000"/>
			<geometry>
				<mesh filename="ModuleLibrary/D86/D86.stl"/>
			</geometry>
			<material name="color-8">
				<color rgba="0.100000 0.100000 0.500000 1.000000"/>
			</material>
		</visual>
		<collision>
			<origin rpy="0.000000 0.000000 0.000000" xyz="0.000000 0.000000 0.000000"/>
			<geometry>
				<mesh filename="ModuleLibrary/D86/D86.stl"/>
			</geometry>
		</collision>
	</link>
	<link name="part10">
		<inertial>
			<origin rpy="0.000000 0.000000 0.000000" xyz="0.000010 -0.000010 0.201369"/>
			<mass value="1.200000"/>
			<inertia ixx="0.063721" ixy="0.000000" ixz="0.000000" iyy="0.063721" iyz="0.000000" izz="0.001004"/>
		</inertial>
		<visual>
			<origin rpy="0.000000 0.000000 0.000000" xyz="0.000000 0.000000 0.000000"/>
			<geometry>
				<mesh filename="ModuleLibrary/L400-I-80-80/L400-I-80-80.stl"/>
			</geometry>
			<material name="color-10">
				<color rgba="1.000000 1.000000 1.000000 1.000000"/>
			</material>
		</visual>
		<collision>
			<origin rpy="0.000000 0.000000 0.000000" xyz="0.000000 0.000000 0.000000"/>
			<geometry>
				<mesh filename="ModuleLibrary/L400-I-80-80/L400-I-80-80.stl"/>
			</geometry>
		</collision>
	</link>
	<link name="part12">
		<inertial>
			<origin rpy="0.000000 0.000000 0.000000" xyz="0.000000 0.000000 -0.022500"/>
			<mass value="0.282000"/>
			<inertia ixx="0.000287" ixy="0.000000" ixz="-0.000000" iyy="0.000287" iyz="-0.000000" izz="0.000122"/>
		</inertial>
	</link>
	<link name="part11">
		<inertial>
			<origin rpy="0.000000 0.000000 0.000000" xyz="0.000620 0.000180 0.058200"/>
			<mass value="1.780000"/>
			<inertia ixx="0.007580" ixy="0.000019" ixz="-0.000074" iyy="0.008140" iyz="-0.000016" izz="0.002150"/>
		</inertial>
		<visual>
			<origin rpy="0.000000 0.000000 0.000000" xyz="0.000000 0.000000 0.000000"/>
			<geometry>
				<mesh filename="ModuleLibrary/D86/D86.stl"/>
			</geometry>
			<material name="color-11">
				<color rgba="0.100000 0.100000 0.500000 1.000000"/>
			</material>
		</visual>
		<collision>
			<origin rpy="0.000000 0.000000 0.000000" xyz="0.000000 0.000000 0.000000"/>
			<geometry>
				<mesh filename="ModuleLibrary/D86/D86.stl"/>
			</geometry>
		</collision>
	</link>
	<link name="tool_dummy">
		<inertial>
			<origin rpy="0.000000 0.000000 0.000000" xyz="0.000620 0.000180 0.058200"/>
			<mass value="0.000000"/>
			<inertia ixx="0.000000" ixy="0.000000" ixz="0.000000" iyy="0.000000" iyz="0.000000" izz="0.000000"/>
		</inertial>
	</link>
	<link name="part14">
		<inertial>
			<origin rpy="0.000000 0.000000 0.000000" xyz="0.000000 0.000000 -0.022500"/>
			<mass value="0.282000"/>
			<inertia ixx="0.000287" ixy="0.000000" ixz="-0.000000" iyy="0.000287" iyz="-0.000000" izz="0.000122"/>
		</inertial>
	</link>
	<link name="part13">
		<inertial>
			<origin rpy="0.000000 0.000000 0.000000" xyz="0.000620 0.000180 0.058200"/>
			<mass value="1.780000"/>
			<inertia ixx="0.007580" ixy="0.000019" ixz="-0.000074" iyy="0.008140" iyz="-0.000016" izz="0.002150"/>
		</inertial>
		<visual>
			<origin rpy="0.000000 0.000000 0.000000" xyz="0.000000 0.000000 0.000000"/>
			<geometry>
				<mesh filename="ModuleLibrary/D86/D86.stl"/>
			</geometry>
			<material name="color-13">
				<color rgba="0.100000 0.100000 0.500000 1.000000"/>
			</material>
		</visual>
		<collision>
			<origin rpy="0.000000 0.000000 0.000000" xyz="0.000000 0.000000 0.000000"/>
			<geometry>
				<mesh filename="ModuleLibrary/D86/D86.stl"/>
			</geometry>
		</collision>
	</link>
	<joint name="part0_part1" type="fixed">
		<origin xyz="-0.070000 0.000000 0.000000" rpy="-0.000000 -1.570796 0.000000"/>
		<parent link="part0"/>
		<child link="part1"/>
		<axis xyz="0.000000 0.000000 0.000000"/>
	</joint>
	<joint name="part2_part3" type="fixed">
		<origin xyz="0.000000 0.000000 0.070500" rpy="0.000000 -0.000000 1.570796"/>
		<parent link="part2"/>
		<child link="part3"/>
		<axis xyz="0.000000 0.000000 0.000000"/>
	</joint>
	<joint name="joint0" type="revolute">
		<origin xyz="0.000000 0.000000 0.082000" rpy="1.570796 -0.000000 1.570796"/>
		<parent link="part1"/>
		<child link="part2"/>
		<axis xyz="0.000000 0.000000 1.000000"/>
		<limit effort="3.141593" velocity="4.390000" lower="-4.712400" upper="4.712400"/>
	</joint>
	<joint name="part4_part5" type="fixed">
		<origin xyz="0.000000 0.000000 0.070500" rpy="0.000000 -0.000000 1.570796"/>
		<parent link="part4"/>
		<child link="part5"/>
		<axis xyz="0.000000 0.000000 0.000000"/>
	</joint>
	<joint name="joint1" type="revolute">
		<origin xyz="0.000000 0.000000 0.082000" rpy="1.570796 -0.000000 1.570796"/>
		<parent link="part3"/>
		<child link="part4"/>
		<axis xyz="0.000000 0.000000 1.000000"/>
		<limit effort="3.141593" velocity="4.390000" lower="-4.712400" upper="4.712400"/>
	</joint>
	<joint name="part5_part6" type="fixed">
		<origin xyz="0.286000 0.000000 0.053000" rpy="0.000000 1.570796 0.000000"/>
		<parent link="part5"/>
		<child link="part6"/>
		<axis xyz="0.000000 0.000000 0.000000"/>
	</joint>
	<joint name="part7_part8" type="fixed">
		<origin xyz="0.000000 0.000000 0.055500" rpy="0.000000 -0.000000 1.570796"/>
		<parent link="part7"/>
		<child link="part8"/>
		<axis xyz="0.000000 0.000000 0.000000"/>
	</joint>
	<joint name="joint2" type="revolute">
		<origin xyz="0.000000 0.000000 0.064000" rpy="1.570796 -0.000000 1.570796"/>
		<parent link="part6"/>
		<child link="part7"/>
		<axis xyz="0.000000 0.000000 1.000000"/>
		<limit effort="3.141593" velocity="7.560000" lower="-4.712400" upper="4.712400"/>
	</joint>
	<joint name="part9_part10" type="fixed">
		<origin xyz="0.000000 0.000000 0.055500" rpy="0.000000 -0.000000 1.570796"/>
		<parent link="part9"/>
		<child link="part10"/>
		<axis xyz="0.000000 0.000000 0.000000"/>
	</joint>
	<joint name="joint3" type="revolute">
		<origin xyz="0.000000 0.000000 0.064000" rpy="1.570796 -0.000000 1.570796"/>
		<parent link="part8"/>
		<child link="part9"/>
		<axis xyz="0.000000 0.000000 1.000000"/>
		<limit effort="3.141593" velocity="7.560000" lower="-4.712400" upper="4.712400"/>
	</joint>
	<joint name="part10_part11" type="fixed">
		<origin xyz="0.000000 0.000000 0.400000" rpy="0.000000 -0.000000 0.000000"/>
		<parent link="part10"/>
		<child link="part11"/>
		<axis xyz="0.000000 0.000000 0.000000"/>
	</joint>
	<joint name="part12_part13" type="fixed">
		<origin xyz="0.000000 0.000000 0.055500" rpy="0.000000 -0.000000 1.570796"/>
		<parent link="part12"/>
		<child link="part13"/>
		<axis xyz="0.000000 0.000000 0.000000"/>
	</joint>
	<joint name="joint4" type="revolute">
		<origin xyz="0.000000 0.000000 0.064000" rpy="1.570796 -0.000000 1.570796"/>
		<parent link="part11"/>
		<child link="part12"/>
		<axis xyz="0.000000 0.000000 1.000000"/>
		<limit effort="3.141593" velocity="7.560000" lower="-4.712400" upper="4.712400"/>
	</joint>
	<joint name="part14_tool_dummy" type="fixed">
		<origin xyz="0.000000 0.000000 0.055500" rpy="0.000000 -0.000000 1.570796"/>
		<parent link="part14"/>
		<child link="tool_dummy"/>
		<axis xyz="0.000000 0.000000 0.000000"/>
	</joint>
	<joint name="joint5" type="revolute">
		<origin xyz="0.000000 0.000000 0.064000" rpy="1.570796 -0.000000 1.570796"/>
		<parent link="part13"/>
		<child link="part14"/>
		<axis xyz="0.000000 0.000000 1.000000"/>
		<limit effort="3.141593" velocity="7.560000" lower="-4.712400" upper="4.712400"/>
	</joint>
</robot>

